Workbook

Sheet Step 1_Config
A1: PRODUCT ID | B1: COUNTRY | C1: Product Name | D1: MARKET TYPE NAME | E1: CLEARING VENUE | F1: MIC CODE
A2: 10 | B2: NWE | C2: Brent 1st Line Future | D2: =_xlfn.XLOOKUP(A2,'ProductCodesReport '!$B:$B,'ProductCodesReport '!$K:$K,1) -> Oil | E2: =_xlfn.XLOOKUP(A2,'ProductCodesReport '!$B:$B,'ProductCodesReport '!$I:$I,1) -> ICEU | F2: =_xlfn.XLOOKUP(A2,'ProductCodesReport '!$B:$B,'ProductCodesReport '!$J:$J,1) -> IFEU
A3: 451 | B3: US | C3: AB NIT Basis Future | D3: =_xlfn.XLOOKUP(A3,'ProductCodesReport '!$B:$B,'ProductCodesReport '!$K:$K,1) -> Financial Gas | E3: =_xlfn.XLOOKUP(A3,'ProductCodesReport '!$B:$B,'ProductCodesReport '!$I:$I,1) -> ICEU | F3: =_xlfn.XLOOKUP(A3,'ProductCodesReport '!$B:$B,'ProductCodesReport '!$J:$J,1) -> IFED
A4: 14 | B4: NWE | C4: Crude Diff - Brent 1st Line vs Dubai 1st Line Future | D4: =_xlfn.XLOOKUP(A4,'ProductCodesReport '!$B:$B,'ProductCodesReport '!$K:$K,1) -> Oil | E4: =_xlfn.XLOOKUP(A4,'ProductCodesReport '!$B:$B,'ProductCodesReport '!$I:$I,1) -> ICEU | F4: =_xlfn.XLOOKUP(A4,'ProductCodesReport '!$B:$B,'ProductCodesReport '!$J:$J,1) -> IFEU
A5: 15 | B5: NWE | C5: Crude Diff - Dated Brent vs Brent 1st Line Future | D5: =_xlfn.XLOOKUP(A5,'ProductCodesReport '!$B:$B,'ProductCodesReport '!$K:$K,1) -> Oil | E5: =_xlfn.XLOOKUP(A5,'ProductCodesReport '!$B:$B,'ProductCodesReport '!$I:$I,1) -> ICEU | F5: =_xlfn.XLOOKUP(A5,'ProductCodesReport '!$B:$B,'ProductCodesReport '!$J:$J,1) -> IFEU
A6: 465 | B6: US | C6: AB NIT Index Future | D6: =_xlfn.XLOOKUP(A6,'ProductCodesReport '!$B:$B,'ProductCodesReport '!$K:$K,1) -> Financial Gas | E6: =_xlfn.XLOOKUP(A6,'ProductCodesReport '!$B:$B,'ProductCodesReport '!$I:$I,1) -> ICEU | F6: =_xlfn.XLOOKUP(A6,'ProductCodesReport '!$B:$B,'ProductCodesReport '!$J:$J,1) -> IFED
A7: 20 | B7: SGP | C7: Fuel Oil 180 CST Singapore Future | D7: =_xlfn.XLOOKUP(A7,'ProductCodesReport '!$B:$B,'ProductCodesReport '!$K:$K,1) -> Oil | E7: =_xlfn.XLOOKUP(A7,'ProductCodesReport '!$B:$B,'ProductCodesReport '!$I:$I,1) -> ICEU | F7: =_xlfn.XLOOKUP(A7,'ProductCodesReport '!$B:$B,'ProductCodesReport '!$J:$J,1) -> IFEU
A8: 20 | B8: SGP | C8: Fuel Oil 180 CST Singapore Future | D8: =_xlfn.XLOOKUP(A8,'ProductCodesReport '!$B:$B,'ProductCodesReport '!$K:$K,1) -> Oil | E8: =_xlfn.XLOOKUP(A8,'ProductCodesReport '!$B:$B,'ProductCodesReport '!$I:$I,1) -> ICEU | F8: =_xlfn.XLOOKUP(A8,'ProductCodesReport '!$B:$B,'ProductCodesReport '!$J:$J,1) -> IFEU
A9: 22 | B9: NWE | C9: Fuel Oil 3.5% FOB Rotterdam Barges Future | D9: =_xlfn.XLOOKUP(A9,'ProductCodesReport '!$B:$B,'ProductCodesReport '!$K:$K,1) -> Oil | E9: =_xlfn.XLOOKUP(A9,'ProductCodesReport '!$B:$B,'ProductCodesReport '!$I:$I,1) -> ICEU | F9: =_xlfn.XLOOKUP(A9,'ProductCodesReport '!$B:$B,'ProductCodesReport '!$J:$J,1) -> IFEU
A10: 22 | B10: NWE | C10: Fuel Oil 3.5% FOB Rotterdam Barges Future | D10: =_xlfn.XLOOKUP(A10,'ProductCodesReport '!$B:$B,'ProductCodesReport '!$K:$K,1) -> Oil | E10: =_xlfn.XLOOKUP(A10,'ProductCodesReport '!$B:$B,'ProductCodesReport '!$I:$I,1) -> ICEU | F10: =_xlfn.XLOOKUP(A10,'ProductCodesReport '!$B:$B,'ProductCodesReport '!$J:$J,1) -> IFEU
A11: 23 | B11: NWE | C11: Fuel Oil 1% FOB NWE Cargoes Future | D11: =_xlfn.XLOOKUP(A11,'ProductCodesReport '!$B:$B,'ProductCodesReport '!$K:$K,1) -> Oil | E11: =_xlfn.XLOOKUP(A11,'ProductCodesReport '!$B:$B,'ProductCodesReport '!$I:$I,1) -> ICEU | F11: =_xlfn.XLOOKUP(A11,'ProductCodesReport '!$B:$B,'ProductCodesReport '!$J:$J,1) -> IFEU
A12: 24 | B12: SGP | C12: Fuel Oil Crack - Fuel Oil 180 CST Singapore vs Dubai 1st Line Future | D12: =_xlfn.XLOOKUP(A12,'ProductCodesReport '!$B:$B,'ProductCodesReport '!$K:$K,1) -> Oil | E12: =_xlfn.XLOOKUP(A12,'ProductCodesReport '!$B:$B,'ProductCodesReport '!$I:$I,1) -> ICEU | F12: =_xlfn.XLOOKUP(A12,'ProductCodesReport '!$B:$B,'ProductCodesReport '!$J:$J,1) -> IFEU
A13: 26 | B13: NWE | C13: Fuel Oil 1% FOB NWE Cargoes vs 3.5% FOB Rotterdam Barges Swap | D13: =_xlfn.XLOOKUP(A13,'ProductCodesReport '!$B:$B,'ProductCodesReport '!$K:$K,1) -> Oil | E13: =_xlfn.XLOOKUP(A13,'ProductCodesReport '!$B:$B,'ProductCodesReport '!$I:$I,1) -> Bilateral | F13: =_xlfn.XLOOKUP(A13,'ProductCodesReport '!$B:$B,'ProductCodesReport '!$J:$J,1) -> ICES
... A23: 22105 | B23: US | C23: Agua Blanca Pool (inter) Physical Gas Daily Spot | D23: =_xlfn.XLOOKUP(A23,'ProductCodesReport '!$B:$B,'ProductCodesReport '!$K:$K,1) -> Physical Gas | E23: =_xlfn.XLOOKUP(A23,'ProductCodesReport '!$B:$B,'ProductCodesReport '!$I:$I,1) -> NGXC | F23: =_xlfn.XLOOKUP(A23,'ProductCodesReport '!$B:$B,'ProductCodesReport '!$J:$J,1) -> IEPA
A24: 183 | B24: US | C24: 1 | D24: =_xlfn.XLOOKUP(A24,'ProductCodesReport '!$B:$B,'ProductCodesReport '!$K:$K,1) -> 1 | E24: =_xlfn.XLOOKUP(A24,'ProductCodesReport '!$B:$B,'ProductCodesReport '!$I:$I,1) -> 1 | F24: =_xlfn.XLOOKUP(A24,'ProductCodesReport '!$B:$B,'ProductCodesReport '!$J:$J,1) -> 1
A25: 186 | B25: US | C25: 1 | D25: =_xlfn.XLOOKUP(A25,'ProductCodesReport '!$B:$B,'ProductCodesReport '!$K:$K,1) -> 1 | E25: =_xlfn.XLOOKUP(A25,'ProductCodesReport '!$B:$B,'ProductCodesReport '!$I:$I,1) -> 1 | F25: =_xlfn.XLOOKUP(A25,'ProductCodesReport '!$B:$B,'ProductCodesReport '!$J:$J,1) -> 1
A26: 222 | B26: MED | C26: Fuel Oil 3.5% FOB Med Cargoes Future | D26: =_xlfn.XLOOKUP(A26,'ProductCodesReport '!$B:$B,'ProductCodesReport '!$K:$K,1) -> Oil | E26: =_xlfn.XLOOKUP(A26,'ProductCodesReport '!$B:$B,'ProductCodesReport '!$I:$I,1) -> ICEU | F26: =_xlfn.XLOOKUP(A26,'ProductCodesReport '!$B:$B,'ProductCodesReport '!$J:$J,1) -> IFEU
A27: 236 | B27: UK | C27: UK NBP Natural Gas Futures | D27: =_xlfn.XLOOKUP(A27,'ProductCodesReport '!$B:$B,'ProductCodesReport '!$K:$K,1) -> IPE Natural Gas Futures | E27: =_xlfn.XLOOKUP(A27,'ProductCodesReport '!$B:$B,'ProductCodesReport '!$I:$I,1) -> ICEU | F27: =_xlfn.XLOOKUP(A27,'ProductCodesReport '!$B:$B,'ProductCodesReport '!$J:$J,1) -> IFEU
A28: 254 | B28: NWE | C28: Brent Crude Futures | D28: =_xlfn.XLOOKUP(A28,'ProductCodesReport '!$B:$B,'ProductCodesReport '!$K:$K,1) -> IPE Brent Futures | E28: =_xlfn.XLOOKUP(A28,'ProductCodesReport '!$B:$B,'ProductCodesReport '!$I:$I,1) -> ICEU | F28: =_xlfn.XLOOKUP(A28,'ProductCodesReport '!$B:$B,'ProductCodesReport '!$J:$J,1) -> IFEU
A29: 257 | B29: NWE | C29: 1 | D29: =_xlfn.XLOOKUP(A29,'ProductCodesReport '!$B:$B,'ProductCodesReport '!$K:$K,1) -> 1 | E29: =_xlfn.XLOOKUP(A29,'ProductCodesReport '!$B:$B,'ProductCodesReport '!$I:$I,1) -> 1 | F29: =_xlfn.XLOOKUP(A29,'ProductCodesReport '!$B:$B,'ProductCodesReport '!$J:$J,1) -> 1
A30: 22108 | B30: US | C30: Agua Blanca Pool (inter) Physical Inside FERC | D30: =_xlfn.XLOOKUP(A30,'ProductCodesReport '!$B:$B,'ProductCodesReport '!$K:$K,1) -> Physical Gas | E30: =_xlfn.XLOOKUP(A30,'ProductCodesReport '!$B:$B,'ProductCodesReport '!$I:$I,1) -> NGXC | F30: =_xlfn.XLOOKUP(A30,'ProductCodesReport '!$B:$B,'ProductCodesReport '!$J:$J,1) -> IEPA
A31: 266 | B31: SGP | C31: Fuel Oil Diff - Fuel Oil 180 CST Singapore vs 380 CST Singapore Future | D31: =_xlfn.XLOOKUP(A31,'ProductCodesReport '!$B:$B,'ProductCodesReport '!$K:$K,1) -> Oil | E31: =_xlfn.XLOOKUP(A31,'ProductCodesReport '!$B:$B,'ProductCodesReport '!$I:$I,1) -> ICEU | F31: =_xlfn.XLOOKUP(A31,'ProductCodesReport '!$B:$B,'ProductCodesReport '!$J:$J,1) -> IFEU
A32: 282 | B32: US | C32: 1 | D32: =_xlfn.XLOOKUP(A32,'ProductCodesReport '!$B:$B,'ProductCodesReport '!$K:$K,1) -> 1 | E32: =_xlfn.XLOOKUP(A32,'ProductCodesReport '!$B:$B,'ProductCodesReport '!$I:$I,1) -> 1 | F32: =_xlfn.XLOOKUP(A32,'ProductCodesReport '!$B:$B,'ProductCodesReport '!$J:$J,1) -> 1
A33: 286 | B33: US | C33: 1 | D33: =_xlfn.XLOOKUP(A33,'ProductCodesReport '!$B:$B,'ProductCodesReport '!$K:$K,1) -> 1 | E33: =_xlfn.XLOOKUP(A33,'ProductCodesReport '!$B:$B,'ProductCodesReport '!$I:$I,1) -> 1 | F33: =_xlfn.XLOOKUP(A33,'ProductCodesReport '!$B:$B,'ProductCodesReport '!$J:$J,1) -> 1
A34: 1881 | B34: US | C34: ANR SE (Louisiana) Basis Future | D34: =_xlfn.XLOOKUP(A34,'ProductCodesReport '!$B:$B,'ProductCodesReport '!$K:$K,1) -> Financial Gas | E34: =_xlfn.XLOOKUP(A34,'ProductCodesReport '!$B:$B,'ProductCodesReport '!$I:$I,1) -> ICEU | F34: =_xlfn.XLOOKUP(A34,'ProductCodesReport '!$B:$B,'ProductCodesReport '!$J:$J,1) -> IFED
A35: 3156 | B35: US | C35: ANR SE (Louisiana) Index Future | D35: =_xlfn.XLOOKUP(A35,'ProductCodesReport '!$B:$B,'ProductCodesReport '!$K:$K,1) -> Financial Gas | E35: =_xlfn.XLOOKUP(A35,'ProductCodesReport '!$B:$B,'ProductCodesReport '!$I:$I,1) -> ICEU | F35: =_xlfn.XLOOKUP(A35,'ProductCodesReport '!$B:$B,'ProductCodesReport '!$J:$J,1) -> IFED
A36: 289 | B36: US | C36: 1 | D36: =_xlfn.XLOOKUP(A36,'ProductCodesReport '!$B:$B,'ProductCodesReport '!$K:$K,1) -> 1 | E36: =_xlfn.XLOOKUP(A36,'ProductCodesReport '!$B:$B,'ProductCodesReport '!$I:$I,1) -> 1 | F36: =_xlfn.XLOOKUP(A36,'ProductCodesReport '!$B:$B,'ProductCodesReport '!$J:$J,1) -> 1
A37: 290 | B37: US | C37: 1 | D37: =_xlfn.XLOOKUP(A37,'ProductCodesReport '!$B:$B,'ProductCodesReport '!$K:$K,1) -> 1 | E37: =_xlfn.XLOOKUP(A37,'ProductCodesReport '!$B:$B,'ProductCodesReport '!$I:$I,1) -> 1 | F37: =_xlfn.XLOOKUP(A37,'ProductCodesReport '!$B:$B,'ProductCodesReport '!$J:$J,1) -> 1
A38: 291 | B38: US | C38: 1 | D38: =_xlfn.XLOOKUP(A38,'ProductCodesReport '!$B:$B,'ProductCodesReport '!$K:$K,1) -> 1 | E38: =_xlfn.XLOOKUP(A38,'ProductCodesReport '!$B:$B,'ProductCodesReport '!$I:$I,1) -> 1 | F38: =_xlfn.XLOOKUP(A38,'ProductCodesReport '!$B:$B,'ProductCodesReport '!$J:$J,1) -> 1
A39: 303 | B39: US | C39: 1 | D39: =_xlfn.XLOOKUP(A39,'ProductCodesReport '!$B:$B,'ProductCodesReport '!$K:$K,1) -> 1 | E39: =_xlfn.XLOOKUP(A39,'ProductCodesReport '!$B:$B,'ProductCodesReport '!$I:$I,1) -> 1 | F39: =_xlfn.XLOOKUP(A39,'ProductCodesReport '!$B:$B,'ProductCodesReport '!$J:$J,1) -> 1
A40: 316 | B40: US | C40: 1 | D40: =_xlfn.XLOOKUP(A40,'ProductCodesReport '!$B:$B,'ProductCodesReport '!$K:$K,1) -> 1 | E40: =_xlfn.XLOOKUP(A40,'ProductCodesReport '!$B:$B,'ProductCodesReport '!$I:$I,1) -> 1 | F40: =_xlfn.XLOOKUP(A40,'ProductCodesReport '!$B:$B,'ProductCodesReport '!$J:$J,1) -> 1
A41: 317 | B41: US | C41: 1 | D41: =_xlfn.XLOOKUP(A41,'ProductCodesReport '!$B:$B,'ProductCodesReport '!$K:$K,1) -> 1 | E41: =_xlfn.XLOOKUP(A41,'ProductCodesReport '!$B:$B,'ProductCodesReport '!$I:$I,1) -> 1 | F41: =_xlfn.XLOOKUP(A41,'ProductCodesReport '!$B:$B,'ProductCodesReport '!$J:$J,1) -> 1
A42: 1834 | B42: US | C42: ANR SE (Louisiana) Physical Basis LD1 | D42: =_xlfn.XLOOKUP(A42,'ProductCodesReport '!$B:$B,'ProductCodesReport '!$K:$K,1) -> Physical Gas | E42: =_xlfn.XLOOKUP(A42,'ProductCodesReport '!$B:$B,'ProductCodesReport '!$I:$I,1) -> NGXC | F42: =_xlfn.XLOOKUP(A42,'ProductCodesReport '!$B:$B,'ProductCodesReport '!$J:$J,1) -> IEPA
A43: 1830 | B43: US | C43: ANR SE (Louisiana) Physical Fixed Price Spot | D43: =_xlfn.XLOOKUP(A43,'ProductCodesReport '!$B:$B,'ProductCodesReport '!$K:$K,1) -> Physical Gas | E43: =_xlfn.XLOOKUP(A43,'ProductCodesReport '!$B:$B,'ProductCodesReport '!$I:$I,1) -> NGXC | F43: =_xlfn.XLOOKUP(A43,'ProductCodesReport '!$B:$B,'ProductCodesReport '!$J:$J,1) -> IEPA
A44: 357 | B44: US | C44: 1 | D44: =_xlfn.XLOOKUP(A44,'ProductCodesReport '!$B:$B,'ProductCodesReport '!$K:$K,1) -> 1 | E44: =_xlfn.XLOOKUP(A44,'ProductCodesReport '!$B:$B,'ProductCodesReport '!$I:$I,1) -> 1 | F44: =_xlfn.XLOOKUP(A44,'ProductCodesReport '!$B:$B,'ProductCodesReport '!$J:$J,1) -> 1
A45: 365 | B45: SGP | C45: Fuel Oil 380 CST Singapore Future | D45: =_xlfn.XLOOKUP(A45,'ProductCodesReport '!$B:$B,'ProductCodesReport '!$K:$K,1) -> Oil | E45: =_xlfn.XLOOKUP(A45,'ProductCodesReport '!$B:$B,'ProductCodesReport '!$I:$I,1) -> ICEU | F45: =_xlfn.XLOOKUP(A45,'ProductCodesReport '!$B:$B,'ProductCodesReport '!$J:$J,1) -> IFEU
A46: 365 | B46: SGP | C46: Fuel Oil 380 CST Singapore Future | D46: =_xlfn.XLOOKUP(A46,'ProductCodesReport '!$B:$B,'ProductCodesReport '!$K:$K,1) -> Oil | E46: =_xlfn.XLOOKUP(A46,'ProductCodesReport '!$B:$B,'ProductCodesReport '!$I:$I,1) -> ICEU | F46: =_xlfn.XLOOKUP(A46,'ProductCodesReport '!$B:$B,'ProductCodesReport '!$J:$J,1) -> IFEU
A47: 368 | B47: US | C47: 1 | D47: =_xlfn.XLOOKUP(A47,'ProductCodesReport '!$B:$B,'ProductCodesReport '!$K:$K,1) -> 1 | E47: =_xlfn.XLOOKUP(A47,'ProductCodesReport '!$B:$B,'ProductCodesReport '!$I:$I,1) -> 1 | F47: =_xlfn.XLOOKUP(A47,'ProductCodesReport '!$B:$B,'ProductCodesReport '!$J:$J,1) -> 1
A48: 369 | B48: US | C48: 1 | D48: =_xlfn.XLOOKUP(A48,'ProductCodesReport '!$B:$B,'ProductCodesReport '!$K:$K,1) -> 1 | E48: =_xlfn.XLOOKUP(A48,'ProductCodesReport '!$B:$B,'ProductCodesReport '!$I:$I,1) -> 1 | F48: =_xlfn.XLOOKUP(A48,'ProductCodesReport '!$B:$B,'ProductCodesReport '!$J:$J,1) -> 1
A49: 375 | B49: US | C49: 1 | D49: =_xlfn.XLOOKUP(A49,'ProductCodesReport '!$B:$B,'ProductCodesReport '!$K:$K,1) -> 1 | E49: =_xlfn.XLOOKUP(A49,'ProductCodesReport '!$B:$B,'ProductCodesReport '!$I:$I,1) -> 1 | F49: =_xlfn.XLOOKUP(A49,'ProductCodesReport '!$B:$B,'ProductCodesReport '!$J:$J,1) -> 1
...

Sheet Step 2_Kew Words
A1: COUNTRY | B1: Product (ProductCodesReport) | C1: Market Type Name (ProductCodesReport ) | D1: MIC CODE (ProductCodesReport )
A2: UK | B2: UK
A3: UK | B3: UKA
A4: SGP | B4: Singapore
A5: NWE | B5: NWE
A6: NWE | B6: Dated Brent
A7: NWE | B7: Eurobob
A8: NWE | B8: ARA
A9: NWE | B9: Brent
A10: NWE | B10: UKC
A11: NL | B11: Dutch TTF
A12: NL | B12: Dutch Power
A13: NL | B13: FOB Rotterdam
... A39: BE | B39: ZEE
A40: CA | C40: Canadian Oilseeds
A41: CA | D41: NGXC
A42: US | B42: CAISO
A43: US | B43: California
A44: US | B44: Oklahoma
A45: US | B45: Chicago
A46: US | B46: AB NIT
A47: US | B47: Agua Blanca Pool
A48: US | B48: ANR SW
A49: US | B49: ANR
A50: US | B50: APC ACE
A51: US | B51: (OPIS)
A52: US | B52: CG Mainline
A53: US | B53: CG Onshore
... A132: US | B132: Algonquin
A133: US | C133: Oil Americas
A134: US | C134: Henry Hub
A135: Global | B135: TD
A136: Global | B136: SYN 1a
A137: Global | B137: Northwest Europe to USAC

Sheet Step 3_Kew Words
A1: COUNTRY | B1: tag 9063/9062 | C1: tag 9301/320 | D1: tag 308
A2: UK | B2: UK
A3: UK | B3: UKA
A4: SGP | B4: Singapore
A5: NWE | B5: NWE
A6: NWE | B6: Dated Brent
A7: NWE | B7: Eurobob
A8: NWE | B8: ARA
A9: NWE | B9: Brent
A10: NWE | B10: UKC
A11: NL | B11: Dutch TTF
A12: NL | B12: Dutch Power
A13: NL | B13: FOB Rotterdam
... A39: BE | B39: ZEE
A40: CA | C40: Canadian Oilseeds
A41: CA | D41: NGXC
A42: US | B42: CAISO
A43: US | B43: California
A44: US | B44: Oklahoma
A45: US | B45: Chicago
A46: US | B46: AB NIT
A47: US | B47: Agua Blanca Pool
A48: US | B48: ANR SW
A49: US | B49: ANR
A50: US | B50: APC ACE
A51: US | B51: (OPIS)
A52: US | B52: CG Mainline
A53: US | B53: CG Onshore
... A132: US | B132: Algonquin
A133: US | C133: Oil Americas
A134: US | C134: Henry Hub
A135: Global | B135: TD
A136: Global | B136: SYN 1a

Sheet ProductCodesReport 
A1: PRODUCT (Click to open in Browser) | B1: PRODUCT ID | C1: PHYSICAL | D1: LOGICAL | E1: GMI FC | F1: R&N A.C.N | G1: GROUP | H1: CLEARING ADMIN | I1: CLEARING VENUE | J1: MIC CODE | K1: MARKET TYPE NAME | L1: SYMBOL CODE
A2: Brent 1st Line Future | B2: 10 | C2: I | D2: BRN | E2: BS | F2: P997 | G2: Crude Oil and Refined Products | H2: Crude Outrights | I2: ICEU | J2: IFEU | K2: Oil | L2: BSP
A3: WTI 1st Line Future | B3: 13 | C3: R | D3: WBS | E3: WS | F3: P996 | G3: Crude Oil and Refined Products | H3: Am Crude | I3: ICEU | J3: IFED | K3: Oil Americas | L3: WSP
A4: Crude Diff - Brent 1st Line vs Dubai 1st Line Future | B4: 14 | C4: BOD | D4: BOD | E4: BO | F4: SF34 | G4: Crude Oil and Refined Products | H4: Crude Diffs | I4: ICEU | J4: IFEU | K4: Oil | L4: BOD
A5: Crude Diff - Dated Brent vs Brent 1st Line Future | B5: 15 | C5: DBF | D5: DBF | G5: Crude Oil and Refined Products | H5: Crude Diffs | I5: ICEU | J5: IFEU | K5: Oil | L5: DBF
A6: Fuel Oil Outright - New York 1% Fuel Oil Future | B6: 19 | C6: FOW | D6: FOW | E6: Q6 | G6: Crude Oil and Refined Products | H6: Am Ref bbl | I6: ICEU | J6: IFED | K6: Oil Americas | L6: FOW
A7: Fuel Oil 180 CST Singapore Future | B7: 20 | C7: SZS | D7: SZS | E7: PE | F7: NM86 | G7: Crude Oil and Refined Products | H7: Ref Outright mt | I7: ICEU | J7: IFEU | K7: Oil | L7: SZS
A8: Fuel Oil 180 CST Singapore Swap | B8: 20 | C8: SZS | D8: SZS | E8: PE | F8: NM86 | G8: Crude Oil and Refined | H8: Ref Outright mt | I8: Bilateral | J8: ICES | K8: Oil | L8: SZS
A9: Fuel Oil 3.5% FOB Rotterdam Barges Future | B9: 22 | C9: BAR | D9: BAR | E9: PG | F9: NM88 | G9: Crude Oil and Refined Products | H9: Ref Outright mt | I9: ICEU | J9: IFEU | K9: Oil | L9: BAR
A10: Fuel Oil 3.5% FOB Rotterdam Barges Swap | B10: 22 | C10: BAR | D10: BAR | E10: PG | F10: NM88 | G10: Crude Oil and Refined | H10: Ref Outright mt | I10: Bilateral | J10: ICES | K10: Oil | L10: BAR
A11: Fuel Oil 1% FOB NWE Cargoes Future | B11: 23 | C11: CAR | D11: CAR | E11: OZ | F11: NM83 | G11: Crude Oil and Refined Products | H11: Ref Outright mt | I11: ICEU | J11: IFEU | K11: Oil | L11: CAR
A12: Fuel Oil 1% FOB NWE Cargoes Swap | B12: 23 | C12: CAR | D12: CAR | E12: OZ | F12: NM83 | G12: Crude Oil and Refined | H12: Ref Outright mt | I12: Bilateral | J12: ICES | K12: Oil | L12: CAR
A13: Fuel Oil Crack - Fuel Oil 180 CST Singapore vs Dubai 1st Line Future | B13: 24 | C13: SES | D13: SES | E13: ML | G13: Crude Oil and Refined Products | H13: Cracks mt | I13: ICEU | J13: IFEU | K13: Oil | L13: SES
A14: Fuel Oil 1% FOB NWE Cargoes vs 3.5% FOB Rotterdam Barges Swap | B14: 26 | C14: FOS | D14: FOS | E14: OX | F14: NM81 | G14: Crude Oil and Refined | H14: Ref Diffs mt | I14: Bilateral | J14: ICES | K14: Oil | L14: FOS
A15: Fuel Oil Diff - Fuel Oil 1% FOB NWE Cargoes vs 3.5% FOB Rotterdam Barges Future | B15: 26 | C15: FOS | D15: FOS | E15: OX | F15: NM81 | G15: Crude Oil and Refined Products | H15: Ref Diffs mt | I15: ICEU | J15: IFEU | K15: Oil | L15: FOS
A16: Heating Oil 1st Line Future | B16: 39 | C16: HOF | D16: UHO | E16: HF | F16: QH59 | G16: Crude Oil and Refined Products | H16: Am Ref bbl | I16: ICEU | J16: IFED | K16: Oil Americas | L16: HOF
A17: Henry LD1 Fixed Price Future | B17: 53 | C17: H | D17: HNG | E17: NN | F17: R754 | G17: Natural Gas | H17: Henry Nat Gas | I17: ICEU | J17: IFED | K17: Henry Hub | L17: HNG
A18: Fuel Oil 3.5% FOB Med Cargoes vs 3.5% FOB Rotterdam Barges Swap | B18: 87 | C18: NVS | D18: NVS | E18: PB | F18: NM85 | G18: Crude Oil and Refined | H18: Ref Diffs mt | I18: Bilateral | J18: ICES | K18: Oil | L18: NVS
A19: Fuel Oil Diff - Fuel Oil 3.5% FOB Med Cargoes vs 3.5% FOB Rotterdam Barges Future | B19: 87 | C19: NVS | D19: NVS | E19: PB | F19: NM85 | G19: Crude Oil and Refined Products | H19: Ref Diffs mt | I19: ICEU | J19: IFEU | K19: Oil | L19: NVS
A20: Fuel Oil Diff - Fuel Oil 180 CST Singapore vs. 3.5% FOB Rotterdam Barges Swap | B20: 88 | C20: SFS | D20: SFS | E20: OW | F20: NM80 | G20: Crude Oil and Refined | H20: Ref Diffs mt | I20: Bilateral | J20: ICES | K20: Oil | L20: SFS
A21: Fuel Oil Diff - Fuel Oil 180 CST Singapore vs 3.5% FOB Rotterdam Barges Future | B21: 88 | C21: SFS | D21: SFS | E21: OW | F21: NM80 | G21: Crude Oil and Refined Products | H21: Ref Diffs mt | I21: ICEU | J21: IFEU | K21: Oil | L21: SFS
A22: Singapore Naphtha Future | B22: 95 | C22: NPT | D22: NPT | E22: Q1 | G22: Crude Oil and Refined Products | H22: RefOutright bbl | I22: ICEU | J22: IFEU | K22: Oil | L22: NPT
A23: Jet Fuel Outright - Singapore Jet Kerosene Future | B23: 124 | C23: SRS | D23: SRS | E23: SR | F23: QH61 | G23: Crude Oil and Refined Products | H23: RefOutright bbl | I23: ICEU | J23: IFEU | K23: Oil | L23: SRS
A24: Singapore Jet Kerosene Swap | B24: 124 | C24: SRS | D24: SRS | E24: SR | F24: QH61 | G24: Crude Oil and Refined | H24: RefOutright bbl | I24: Bilateral | J24: ICES | K24: Oil | L24: SRS
A25: Fuel Oil Crack - USGC HSFO (Platts) vs WTI 1st Line Future | B25: 166 | C25: GUF | D25: GUF | E25: Q3 | G25: Crude Oil and Refined Products | H25: Am Cracks bbl | I25: ICEU | J25: IFED | K25: Oil Americas | L25: GUF
A26: Crude Diff - WTI vs Brent Bullet Future | B26: 171 | C26: TIB | D26: TIB | E26: U- | G26: Crude Oil and Refined Products | H26: Am Crude Diffs | I26: ICEU | J26: IFED | K26: Oil Americas | L26: TIB
A27: Brent Bullet Future | B27: 187 | C27: BNB | D27: BRN | E27: BN | F27: SG25 | G27: Crude Oil and Refined Products | H27: Crude Outrights | I27: ICEU | J27: IFEU | K27: Oil | L27: BNB
A28: Fuel Oil Diff - Fuel Oil 1% FOB Rotterdam Barges vs 1% FOB NWE Cargoes Future | B28: 200 | C28: FBC | D28: FBC | E28: FB | F28: QH72 | G28: Crude Oil and Refined Products | H28: Ref Diffs mt | I28: ICEU | J28: IFEU | K28: Oil | L28: FBC
A29: Fuel Oil 3.5% FOB Med Cargoes Future | B29: 222 | C29: FOM | D29: FOM | E29: 5 | F29: T034 | G29: Crude Oil and Refined Products | H29: Ref Outright mt | I29: ICEU | J29: IFEU | K29: Oil | L29: FOM
A30: Fuel Oil 1% FOB Rotterdam Barges Future | B30: 223 | C30: FOB | D30: FOB | E30: FO | F30: QH73 | G30: Crude Oil and Refined Products | H30: Ref Outright mt | I30: ICEU | J30: IFEU | K30: Oil | L30: FOB
A31: UK NBP Natural Gas Futures | B31: 236 | C31: M | D31: GWM | E31: WM | F31: 960 | G31: Natural Gas | H31: IPE Nat Gas | I31: ICEU | J31: IFEU | K31: IPE Natural Gas Futures | L31: GWM
A32: Brent Crude Futures | B32: 254 | C32: B | D32: BRN | E32: BC | F32: 952 | G32: Crude Oil and Refined Products | H32: IPE e-Brent | I32: ICEU | J32: IFEU | K32: IPE Brent Futures | L32: BRN
A33: Henry Penultimate Fixed Price Future | B33: 261 | C33: PHE | D33: HNG | E33: PH | F33: O759 | G33: Natural Gas | H33: Henry Hub (Pen) | I33: ICEU | J33: IFED | K33: Henry Hub | L33: PHE
A34: Fuel Oil Diff - Fuel Oil 180 CST Singapore vs 380 CST Singapore Future | B34: 266 | C34: STS | D34: STS | E34: ST | F34: QH63 | G34: Crude Oil and Refined Products | H34: Ref Diffs mt | I34: ICEU | J34: IFEU | K34: Oil | L34: STS
A35: Palo Verde Day-Ahead Peak Fixed Price Future | B35: 287 | C35: PVM | D35: PVM | E35: PV | F35: O940 | G35: Electricity | H35: Pwr West Term | I35: ICEU | J35: IFED | K35: Financial Power | L35: PVM
A36: CAISO SP-15 Day-Ahead Peak Fixed Price Future | B36: 288 | C36: SPM | D36: SPM | E36: SP | F36: O939 | G36: Electricity | H36: Pwr West Term | I36: ICEU | J36: IFED | K36: Financial Power | L36: SPM
A37: Mid-Columbia Day-Ahead Peak Fixed Price Future | B37: 318 | C37: MDC | D37: MDC | E37: MC | F37: N712 | G37: Electricity | H37: Pwr West Term | I37: ICEU | J37: IFED | K37: Financial Power | L37: MDC
A38: CAISO NP-15 Day-Ahead Peak Fixed Price Future | B38: 319 | C38: NPM | D38: NPM | E38: NP | F38: N713 | G38: Electricity | H38: Pwr West Term | I38: ICEU | J38: IFED | K38: Financial Power | L38: NPM
A39: Fuel Oil 380 CST Singapore Future | B39: 365 | C39: SYS | D39: SYS | E39: PF | F39: NM87 | G39: Crude Oil and Refined Products | H39: Ref Outright mt | I39: ICEU | J39: IFEU | K39: Oil | L39: SYS
A40: Fuel Oil 380 CST Singapore Swap | B40: 365 | C40: SYS | D40: SYS | E40: PF | F40: NM87 | G40: Crude Oil and Refined | H40: Ref Outright mt | I40: Bilateral | J40: ICES | K40: Oil | L40: SYS
...
